Workbook

Sheet Leia-me
A1: Planilha de triagem – Síndrome de Edwards (T18): sobrevida e desfecho gestacional
A3: Buscas: data, horário e número de registros
A4: Busca A – registros recuperados para a triagem: 29/09/2026, 19h21 (horário de Brasília; 22h21 UTC) – 253 registros
A5: Busca B – registros recuperados para a triagem: 29/09/2026, 19h21 (horário de Brasília; 22h21 UTC) – 241 registros
A6: Buscas A e B – reexecução de conferência: 29/09/2026, 19h48 (horário de Brasília; 22h48 UTC) – 253 e 241 registros; mesmos 449 registros distintos
A7: Busca A – execução pelo pesquisador na interface do PubMed: 29/09/2026, 19h20 (horário de Brasília; 22h21 UTC) – 253 registros
A8: Busca B – execução pelo pesquisador na interface do PubMed: 29/09/2026, 19h47 (horário de Brasília; 22h48 UTC) – 241 registros
A9: Base: PubMed. Os horários de 19h21 e 19h48 correspondem à recuperação dos registros pela interface de programação do PubMed (E-utilities) e foram registrados pelo sistema de arquivos do ambiente de trabalho. Um minuto antes de cada uma delas, o pesquisador rodou as buscas na interface do site.
A11: Desenho da revisão: três revisores de IA independentes e arbitragem humana
A12: Revisor 1 – Claude (Anthropic): triagem inicial de título e resumo, registrada na aba Triagem.
A13: Revisor 2 – Gemini (Google): revisão independente, registrada na aba Revisão_Gemini.
A14: Revisor 3 – ChatGPT (OpenAI): revisão independente, registrada na aba Revisão_ChatGPT.
... A80: 4. Abas de revisão: a versão do modelo aparece como "3.0" (Gemini) e "1.0" (ChatGPT). Registrar o nome completo do modelo (por exemplo, o que a própria interface informa), para que a revisão seja reproduzível.

Sheet Prompt_revisores
A1: Texto padronizado para o Gemini e o ChatGPT (copiar e colar sem alterações, seguido do lote de registros)
A3: Você é um revisor independente de uma triagem de literatura científica (etapa de título e resumo) para um artigo jurídico sobre a síndrome de Edwards (trissomia 18, T18).
A4: PERGUNTA A: estudos com dados de sobrevida ou mortalidade de nascidos vivos com T18.
A5: PERGUNTA B: estudos com dados sobre o desfecho de gestações após diagnóstico pré-natal de T18 (nascido vivo, perda espontânea, óbito fetal, natimorto).
A6: INCLUIR: dados originais de sobrevida/mortalidade (A) ou de desfecho gestacional (B), específicos para T18 ou separáveis de outras condições; ou revisões sistemáticas desses estudos. Séries de casos são aceitas; relatos de caso isolados não.
A7: APOIO: textos sem dados de desfecho, mas úteis ao debate (diretrizes, consensos, ética, terminologia, qualidade de vida, contrapontos).
A8: EXCLUIR, com um código: E1 fora do tema (não trata da síndrome como objeto); E2 rastreamento/diagnóstico pré-natal sem desfecho específico da T18; E3 outra anomalia como objeto, T18 só como achado associado; E4 sem dados próprios e sem utilidade direta; E5 sem desfecho de sobrevida ou gestacional; E6 relato de caso ou capítulo; E7 T18 não é objeto ou dados não separáveis; E8 prevalência/epidemiologia sem desfecho; E9 apenas trissomia parcial ou mosaico.
A9: REGRAS: (1) decida SOMENTE com base no título e no resumo fornecidos; não use conhecimento externo sobre o artigo e não pesquise na internet; (2) não invente informações que não estejam no resumo; (3) se a informação for insuficiente para decidir, escolha Incluir e escreva 'informação insuficiente – verificar texto completo'; (4) avalie todas as linhas do lote, sem omitir nenhuma.
A10: FORMATO DA RESPOSTA: uma tabela com as colunas PMID | Decisão (Incluir, Excluir ou Apoio) | Pergunta (A, B ou A+B, só se Incluir) | Código (E1 a E9, só se Excluir) | Justificativa (uma frase citando o elemento do título ou do resumo que fundamenta a decisão). Mantenha a mesma ordem das linhas recebidas.

Sheet Triagem
A1: PMID | B1: Ano | C1: Primeiro autor | D1: Título | E1: Resumo | F1: Periódico | G1: Tipo de publicação | H1: Busca | I1: Decisão – Claude | J1: Pergunta – Claude | K1: Código – Claude | L1: Motivo / descrição | M1: Nota | N1: Link PubMed | O1: Ano ≥ 2024
A2: 40831321 | B2: 2026 | C2: Nemoto S | D2: Current Nationwide Landscape of Cardiac Surgery for Children With Trisomy 18 in Japan. | E2: Despite the increasing number of retrospective cohorts describing successful cardiac surgery for children with trisomy 18, no consensus has been reached among healthcare providers regarding cardiac surgery in Japan. This study provided a benchmark to facilitate consensus building by assessing a nationwide surgical database in Japan. A total of 78,179 cardiothoracic surgeries performed for children with congenital heart disease were registered in the Japan Cardiovascular Surgery Database Congenital Section from 2013 to 2021. Of these, 789 (1.0%) surgeries were performed for 502 children with trisomy 18 with increasing yearly trends. Of these, 490 cases (96.1%) of mild-to-moderate cardiac lesions underwent simple surgery, whereas 600 closed-heart surgeries accounted for 76.0%. Approximately 19.4% of the cases were associated with noncardiac lesions that led to postoperative complications at a frequency of 35.3%, whereas cardiac-related postoperative complications accounted for 30.5%. Severe infections occurred postoperatively in approximately 9% of the cases. Forty-two (8.4%) patients died in-hospital, of which the most common cause was heart-related, followed by respiratory-related and infection. This nationwide database analysis may provide valuable information that may serve as a benchmark and enable us to better define the patient attributes that will maximize the effectiveness of cardiac surgery for the vulnerable children. | F2: Am J Med Genet A | G2: Journal Article | H2: A | I2: Incluir | J2: A | N2: =HYPERLINK("https://pubmed.ncbi.nlm.nih.gov/40831321/","abrir") -> abrir | O2: =IF(B2 < 2024, FALSE() , TRUE()) -> TRUE
A3: 41485045 | B3: 2026 | C3: Caggiano S | D3: Survival in infants with trisomy 18, palliative care and ethical reflections: a single center considerations. | E3: BACKGROUND: Trisomy 18 was once considered a fatal diagnosis due to the presence of cardiac and extracardiac lesions. However, with the increasing use of therapeutic management, 3% to 25% of infants with trisomy 18 may survive beyond their first year, depending on the interventions provided. Currently, there are no clear and widely accepted criteria to guide medical decisions for children with trisomy 18. This means that patients could often be at risk of either over-treatment or therapeutic abandonment. We aimed to explore the effectiveness of intensive and non-intensive treatments in enhancing the clinical burden of disease and survival of children with trisomy 18 syndrome METHODS: a retrospective monocentric study in Bambino Gesù Children’s Hospital, IRCCS Rome, Italy. We enrolled all patients discharged from our hospital with genetic diagnosis of trisomy 18 between 2018 and 2023. Clinical data from birth were collected and categorized into two groups: those who received intensive treatment and those who underwent a palliative approach. Intensive treatment was defined as corrective heart surgery, use of invasive respiratory support, or at least one hospitalization in an intensive care unit. Survival probabilities at different age intervals were calculated, and the clinical burden of disease was assessed, taking into account device dependence, number of emergency department visits per year, and the daily intake of medications at home RESULTS: 32 patients were enrolled. Children with a low device dependence had significantly higher survival(p= 0,01). Neither palliative nor corrective heart surgery affected survival for patients with major cardiac defects. Conversely in children with minor heart defects surgery significantly increased survival probability(p= 0.01), particularly the corrective approach(p= 0.01). High number of emergency department visits(p=0.03) and high number of drugs taken daily(p=0.02) significantly reduced survival. No significant differences emerged between the two groups in terms of burden of disease. CONCLUSIONS: proportional to the initial clinical conditions all treatment options, which may include both comfort care and heart surgery, should be re-evaluated to determine the approach that prioritizes the best interest of each child with trisomy 18. | F3: Ital J Pediatr | G3: Journal Article | H3: A | I3: Incluir | J3: A | N3: =HYPERLINK("https://pubmed.ncbi.nlm.nih.gov/41485045/","abrir") -> abrir | O3: =IF(B3 < 2024, FALSE() , TRUE()) -> TRUE
A4: 41749627 | B4: 2026 | C4: Uygur Külcü N | D4: Trisomy 18 and Trisomy 13: A Retrospective Cohort Study at a Tertiary Hospital. | E4: BACKGROUND: Trisomy 18 (T18; Edwards syndrome) and Trisomy 13 (T13; Patau syndrome) are rare autosomal aneuploidies characterized by severe congenital anomalies, high neonatal mortality, and complex clinical trajectories. OBJECTIVE: This study aimed to describe the clinical features, management approaches, and outcomes of genetically confirmed patients aged 0-18 years diagnosed with T18 or T13 in a tertiary care center. METHODS: This retrospective study reviewed hospital records of genetically confirmed T18 and T13 cases identified through ICD-10 codes (Q91-Q92) between January 2015 and December 2024. Patients aged 0-18 years at diagnosis were included. Demographic, clinical, and interventional data were collected from electronic medical records. Survival analyses were conducted using the Kaplan-Meier method, with comparisons assessed using the log-rank test. RESULTS: Among 29 patients, 23 had T18 and 6 had T13. Cardiovascular involvement was the most frequent anomaly, and overall mortality was high despite intensive care. Median survival was 90 days for T18 and 120 days for T13, with more than 80% surviving the first month but showing a steep decline thereafter. Most deaths were attributed to cardiopulmonary complications or sepsis secondary to prolonged intensive care. Kaplan-Meier analysis revealed marked early mortality in both groups, with no significant survival difference (log-rank p ≈ 0.3). A small subset demonstrated longer-term survival with heterogeneous clinical courses. CONCLUSIONS: T18 and T13 are associated with high early mortality driven by complex congenital heart disease, respiratory instability, and infection-related complications. Although the overall prognosis remains poor, a minority of patients achieve extended survival, highlighting variable trajectories. Early multidisciplinary care, individualized decision-making, and strict infection prevention remain essential to optimize outcomes and support families. | F4: Children (Basel) | G4: Journal Article | H4: A | I4: Incluir | J4: A | N4: =HYPERLINK("https://pubmed.ncbi.nlm.nih.gov/41749627/","abrir") -> abrir | O4: =IF(B4 < 2024, FALSE() , TRUE()) -> TRUE
A5: 41840151 | B5: 2026 | C5: Sugai S | D5: Annual trends and regional variations in medical interventions and survival to discharge for trisomies 18 and 13, 2011-2022: a nationwide inpatient database study. | E5: OBJECTIVE: This study examines annual trends and regional disparities in interventions and in-hospital outcomes for trisomies 18 and 13. STUDY DESIGN: We conducted a retrospective cohort study using nationwide data from 2011 to 2022. Patients with trisomies 18 and 13 admitted on the day of birth were identified. Nonsurgical and surgical intervention rates, survival to discharge, length of stay, and costs were analyzed by year and region. RESULT: This study identified 2 245 neonates with trisomy 18 (n = 1 808) and trisomy 13 (n = 437). Nonsurgical and surgical intervention rates increased annually. Between 2011 and 2022, survival to discharge rates improved from 44.5 to 57.9%, and both hospital length of stay and costs nearly doubled. Regional disparities in survival to discharge rates were significant, with differences of up to 21.5%. CONCLUSION: We observed an increase in interventions and a corresponding improvement in survival to discharge, with significant regional variations. | F5: J Perinatol | G5: Journal Article | H5: A | I5: Incluir | J5: A | M5: Coorte nacional japonesa 2011–2022 (1.808 T18). | N5: =HYPERLINK("https://pubmed.ncbi.nlm.nih.gov/41840151/","abrir") -> abrir | O5: =IF(B5 < 2024, FALSE() , TRUE()) -> TRUE
A6: 42302673 | B6: 2026 | C6: Lee T | D6: Characteristics and Outcomes of Pediatric Trisomy 13 and 18 Inpatient Admissions in Texas. | E6: INTRODUCTION: Trisomy 13 (T13, Patau syndrome) and trisomy 18 (T18, Edwards syndrome) are the second and third most common aneuploidies with significant morbidity and mortality. Survival beyond infancy is becoming increasingly recognized. However, surgical needs of these populations are not well described. We aim to investigate the characteristics and outcomes of the surgical care of pediatric patients with T13 and T18 in Texas. METHODS: The Texas Hospital Inpatient Discharge Public Use Data File (2017-2023) was queried to identify all pediatric admissions (<18 y) with T13 and T18 using International Classification of Diseases, Tenth Revision codes. Therefore, transfers to outside hospital were excluded to avoid systematic double counting. Descriptive statistics were performed (median, [interquartile range]). RESULTS: A total of 582 admissions were identified (181 T13, 401 T18). The majority of admissions occurred in the first year of life. Overall inpatient mortality rates were high in both (T13 27.1%, T18 23.7%) with highest mortality in neonates (≤28 d; T13 65.6%, T18 56.4%). Notably, inpatient mortality in older admissions dramatically decreased. Across all age groups, length of stay and median charges were highest for infants (29-365 d) (T13 length of stay 17 d [3-31], T18 16 d [5-43]) with frequent operative interventions, which persisted throughout childhood. While cardiovascular anomalies were prevalent in the younger cohort, supportive operative interventions including airway, vascular, and feeding access were the most common procedures. CONCLUSIONS: While T13 and T18 both have high mortality, particularly in infancy, there is survival with persistent health-care utilization and operative needs throughout childhood. This highlights significant long-term health-care needs and evolving surgical indications. Longitudinal care coordination of multidisciplinary surgical care is needed to optimize outcomes of affected patients. | F6: J Surg Res | G6: Journal Article | H6: A | I6: Incluir | J6: A | N6: =HYPERLINK("https://pubmed.ncbi.nlm.nih.gov/42302673/","abrir") -> abrir | O6: =IF(B6 < 2024, FALSE() , TRUE()) -> TRUE
A7: 42437037 | B7: 2026 | C7: Koshida S | D7: Poorer survival in prenatally diagnosed trisomy 18 infants compared with postnatally diagnosed cases: a single-center study. | E7: BACKGROUND: Trisomy 18 is a common autosomal trisomy that is associated with high perinatal and infant mortality rates. With the widespread use of prenatal screening, many cases have been identified. In contrast, when the diagnosis occurs in the late prenatal period, that is, beyond the gestational limit for termination, or postnatally, careful planning for delivery and neonatal care is required. Emerging evidence suggests that intensive neonatal care can prolong survival and that the prenatal diagnosis may influence subsequent treatment choices. However, few studies have directly compared survival according to the timing of the diagnosis while accounting for treatment policy. Therefore, we compared survival between prenatally and postnatally diagnosed infants with trisomy 18, and examined whether diagnostic timing was associated with the selection of intensive care. METHODS: A retrospective study was conducted on 35 cases of trisomy 18 identified at our center between 2005 and 2024, including 25 prenatally diagnosed cases and 10 postnatally diagnosed liveborn infants. Among the prenatally diagnosed cases, 15 resulted in live births. Survival outcomes were compared between prenatally diagnosed liveborn infants (n = 15) and postnatally diagnosed liveborn infants (n = 10), and perinatal characteristics were evaluated. RESULTS: Among all liveborn infants, the Kaplan-Meier estimated 12-month survival rates were 8% (95% CI [0.5%-30.6%]) in the prenatal group and 40% (95% CI [12.3%-67.0%]) in the postnatal group, with poorer survival in the prenatal group (log-rank p = 0.02). Among liveborn infants, an intensive care policy was selected significantly less frequently in the prenatal group than in the postnatal group (33.3% [5/15] vs. 90.0% [9/10], p = 0.01). In an exploratory subgroup analysis of infants who received intensive care, the Kaplan-Meier estimated 12-month survival rates were 20% (95% CI [0.8%-58.2%]) in the prenatal group and 44% (95% CI [13.6%-71.9%]) in the postnatal group. The confidence intervals were wide, and no statistically significant difference in survival was observed between the two groups (log-rank p = 0.30). CONCLUSIONS: Overall survival was poorer among infants with trisomy 18 diagnosed prenatally than among those diagnosed postnatally, and this difference may be partly associated with differences in treatment policies. These findings suggest that treatment policies following prenatal diagnosis may be associated with survival duration in trisomy 18. | F7: PeerJ | G7: Journal Article; Comparative Study | H7: A+B | I7: Incluir | J7: A | M7: Destaque: compara diagnóstico pré-natal e pós-natal. | N7: =HYPERLINK("https://pubmed.ncbi.nlm.nih.gov/42437037/","abrir") -> abrir | O7: =IF(B7 < 2024, FALSE() , TRUE()) -> TRUE
A8: 42599515 | B8: 2026 | C8: Nagao H | D8: Survival Benefit and Persistent Hospitalization Burden After Ventricular Septal Defect Closure in Infants with Trisomy 18 Headings: Hospitalization After VSD Closure in Trisomy 18. | E8: This retrospective study evaluated the impact of ventricular septal defect (VSD) closure on long-term survival and hospitalization status in infants with trisomy 18. Thirty-three infants with trisomy 18 and VSD (2002-2025) were categorized into three groups: staged VSD closure following pulmonary artery banding (PAB) (n = 7), PAB alone (n = 3), or non-surgical management (n = 23). Median follow-up durations (interquartile range) were 124.6 (75.8-153.1), 17.8 (11.4-18.1), and 17.1 (2.7-59.3) months, respectively. Kaplan-Meier analysis demonstrated significantly better survival in the VSD closure group (log-rank p = 0.009). However, these survivors required frequent unexpected hospitalizations for non-cardiac comorbidities. In univariate negative binomial regression, respiratory and digestive complications were significantly associated with higher unexpected admission rates (incidence rate ratio [IRR] = 1.07, 95% confidence interval [CI]: 1.02-1.12; and IRR = 1.24, 95% CI: 1.08-1.41, respectively; p < 0.01). After multivariable adjustment, only digestive complications showed a notable, though non-significant, trend (IRR = 1.15, 95% CI: 0.98-1.36, p = 0.09). Notably, VSD closure was associated with a higher admission rate in univariate analysis (IRR = 1.95, 95% CI: 0.95-4.00, p = 0.07), but this association disappeared after multivariable adjustment. VSD closure was associated with improved survival in infants with trisomy 18, but a substantial hospitalization burden persisted due to non-cardiac comorbidities. These findings highlight the importance of lifelong multidisciplinary care and detailed parental counseling regarding the expected long-term medical burden following VSD closure. | F8: Pediatr Cardiol | G8: Journal Article | H8: A | I8: Incluir | J8: A | N8: =HYPERLINK("https://pubmed.ncbi.nlm.nih.gov/42599515/","abrir") -> abrir | O8: =IF(B8 < 2024, FALSE() , TRUE()) -> TRUE
A9: 42634104 | B9: 2026 | C9: Rodriguez LC | D9: Congenital Heart Disease Associated With Genetic Syndromes and Extracardiac Anomalies: A Six-Year Epidemiological Study in a Brazilian Referral Center. | E9: BACKGROUND: Congenital heart diseases (CHDs) are structural and/or functional abnormalities of the heart that arise during embryonic cardiovascular development. They are the most common type of congenital defect and represent a major cause of neonatal morbidity and mortality, particularly when associated with genetic syndromes or other congenital anomalies. This study aims to analyze the clinical and epidemiological profile of CHD in newborns at a high fetal-risk maternity hospital in Rio de Janeiro from 2018 to 2023, describing the types of CHD, associated anomalies and genetic syndromes, maternal risk factors, and neonatal outcomes. METHODS: This is a descriptive, retrospective study using the database of the Latin American Collaborative Study of Congenital Malformations (ECLAMC) at Instituto Fernandes Figueira/Fiocruz (IFF/Fiocruz). Newborns with a confirmed diagnosis of CHD, born at IFF between January 2018 and December 2023 and properly registered in the ECLAMC program were included. RESULTS: Among 5647 births, 225 newborns with CHD were identified and analyzed, corresponding to a prevalence of approximately 4%. The most frequent CHD was ventricular septal defect (VSD), present in 68 cases, followed by atrioventricular septal defect (AVSD) in 41 cases and coarctation of the aorta (CoA) in 27. Complex cardiopathies predominated, representing 60% of cases. Most diagnoses were established prenatally (93.3%), with a fetal echocardiogram accuracy of 78.5%. Associated congenital anomalies were identified in 64% of cases, predominantly affecting the gastrointestinal tract, central nervous system, and genitourinary tract. Genetic syndromes were confirmed in 95 patients (42.2%), with a predominance of Down syndrome (35), followed by Edwards syndrome (29) and Patau syndrome (10). The rate of hospital discharge alive was 53.3% in patients with isolated CHD, compared to 29% in those with associated syndromes or anomalies. CONCLUSIONS: IFF presents a highly complex patient profile, with a high prevalence of CHD associated with genetic syndromes and extracardiac anomalies, reflecting its role as a tertiary referral center. The presence of associated anomalies and syndromes negatively impacted neonatal prognosis, reinforcing the importance of prenatal diagnosis and specialized multidisciplinary care in the management of these conditions. | F9: Birth Defects Res | G9: Journal Article | H9: A | I9: Incluir | J9: A | M9: Verificar no texto completo se há dado específico e separável da T18 | N9: =HYPERLINK("https://pubmed.ncbi.nlm.nih.gov/42634104/","abrir") -> abrir | O9: =IF(B9 < 2024, FALSE() , TRUE()) -> TRUE
A10: 42746679 | B10: 2026 | C10: Fonseca Queiroz L | D10: Intensive versus comfort-focused care in neonates with trisomy 18: A systematic review and meta-analysis. | E10: ObjectiveTo evaluate whether intensive neonatal interventions improve survival outcomes compared with comfort-focused care in neonates with Trisomy 18.Study designWe conducted a systematic review and pairwise meta-analysis of observational studies reporting outcomes for neonates with Trisomy 18 receiving either intensive or comfort-focused care. Databases searched included PubMed, Embase, and Cochrane Central Register up to March 2026. Outcomes included mean survival days and 1-year survival as primary outcomes, and gestational age at delivery as a secondary exploratory outcome.ResultsFive observational studies including 211 patients were analyzed (133 received intensive care, and 78 received comfort-focused care). Pooled analyses showed no statistically significant differences between groups for mean survival days (MD -225.53 days; 95% CI -776.85 to 325.79), 1-year survival (RR 1.12; 95% CI 0.90 to 1.40), or gestational age at birth (MD -0.28 weeks; 95% CI -1.69 to 1.13).ConclusionDespite the absence of a demonstrated survival benefit of intensive neonatal interventions over non-intensive care in Trisomy 18, the findings should be interpreted cautiously given the small number of available studies, substantial clinical and statistical heterogeneity, and very low certainty of evidence. Findings highlight the importance of individualized, informed decision-making guided by prenatal counseling that integrates evidence-based outcomes and parental values. High-quality, multicenter prospective studies are needed to evaluate the impact of specific interventions and improve guidance for families and clinicians. | F10: J Neonatal Perinatal Med | G10: Journal Article; Review | H10: A | I10: Incluir | J10: A | M10: Destaque: revisão sistemática com metanálise mais recente (set/2026), cuidado intensivo x cuidado de conforto. | N10: =HYPERLINK("https://pubmed.ncbi.nlm.nih.gov/42746679/","abrir") -> abrir | O10: =IF(B10 < 2024, FALSE() , TRUE()) -> TRUE
A11: 42764676 | B11: 2026 | C11: Matsushima A | D11: Acute Healthcare Utilization During the First Year After Hospital Discharge in Children With Trisomy 18. | E11: Survival of infants with trisomy 18 (T18) has improved with advances in neonatal intensive care and surgical management, yet postdischarge outcomes remain poorly characterized. This single-center retrospective cohort study included infants with T18 admitted to a Level III neonatal intensive care unit between 2008 and 2022. Survival and survival-to-discharge rates were analyzed by birth era. For patients discharged alive in the most recent era (2018-2022), emergency department (ED) visits and hospital admissions during the first year after discharge were evaluated. Among 87 infants with confirmed outcomes, overall survival and survival-to-discharge rates improved over time. Sixteen patients discharged alive in the late cohort were included in the postdischarge analysis. During the first year after discharge, 13 patients (81%) visited the ED at least once, and 11 (69%) required hospital admission. Respiratory disorders were the most frequent reason for admission, followed by urinary tract infections and gastrointestinal disorders. An exploratory analysis found no significant association between tracheostomy status and ED visits or hospital admissions. Two patients died within 1 year after discharge. Despite improving survival, infants with T18 experience substantial healthcare utilization after discharge, underscoring the need for structured multidisciplinary follow-up and robust home-based care support systems. | F11: Am J Med Genet A | G11: Journal Article | H11: A | I11: Incluir | J11: A | N11: =HYPERLINK("https://pubmed.ncbi.nlm.nih.gov/42764676/","abrir") -> abrir | O11: =IF(B11 < 2024, FALSE() , TRUE()) -> TRUE
A12: 39821650 | B12: 2025 | C12: Visconti D | D12: Trisomy 18 and the possibility of choice: The importance of Perinatal Hospice's support. | E12: Trisomy 18 is a severe aneuploidy associated with multiple malformations and a poor prognosis. The diagnosis is typically made prenatally, leading to a high rate of pregnancy terminations. The aim of this study is to demonstrate that even though the prognosis is heterogeneous, prolonged survival is possible and these children are an enrichment for their families after all. A retrospective, descriptive and monocentric study was conducted on fetuses diagnosed with trisomy 18, evaluated between March 2017 and June 2023 at our Institution. The objective was to investigate the natural history of trisomy 18 and the psychological impact on parents who choose to carry the pregnancy on, through a retrospective data collection and the use of a questionnaire. Sixteen couples with a diagnosis of trisomy 18 were cared for within the Perinatal Hospice Pathway during the study period. Cardiac defects were identified in 93.7% of cases, structural abnormalities in 71.4%, respiratory defects in 14.3% of the fetuses, while genitourinary defects affected nearly half of the study population. The survival rate was typically less than one day, however two babies survived for more than four years. All couples reported being satisfied with their decision to continue the pregnancy and would do so again if given the opportunity.Conclusions: despite the severity of the diagnosis, couples may choose to continue the pregnancy and give birth. Our study shows that trisomy 18 is not merely a lethal condition and the Perinatal Hospice plays a crucial role in supporting these families. | F12: Eur J Pediatr | G12: Journal Article | H12: A+B | I12: Incluir | J12: A+B | N12: =HYPERLINK("https://pubmed.ncbi.nlm.nih.gov/39821650/","abrir") -> abrir | O12: =IF(B12 < 2024, FALSE() , TRUE()) -> TRUE
A13: 39854275 | B13: 2025 | C13: Nemoto S | D13: Closure of ventricular septal defect in children with trisomy 18: perioperative events and long-term survival. | E13: OBJECTIVES: This retrospective study aimed to investigate the feasibility of surgical closure of ventricular septal defect in children with trisomy 18 by assessing perioperative events and long-term survival. METHODS: From April 2008 to March 2024, 41 consecutive patients were referred to us for ventricular septal defect surgery. The defect was closed in 35 patients at the end (median age, 16 months; median body weight, 5.7 kg), 31 out of 37 patients after the preceding pulmonary artery banding according to our staged surgery policy and 4 patients without the banding. Sixty-five significant non-cardiac lesions existed concurrently, and 14 patients underwent tracheostomy before closure. The investigation was conducted by checking medical records and contacting the primary physician. RESULTS: Four patients died during the inter-stage after banding to closure (10.8%). Two of them were awaiting closure. Concomitant surgeries, 15 right ventricular muscle resections, or 1 arch repair, were performed along with closure. Arrhythmia was the most common adverse event (51.4%). Three patients required extracorporeal membrane oxygenation support. Transient but severe hepatic injury occurred in 11 patients (31.4%). There were two hospital death (5.7%) due to severe respiratory insufficiency or fulminant sepsis. Five patients died after discharge, three pneumonia and two sudden death, resulting in a 5-year estimated survival of 79.5%. Three hepatoblastoma and one hepatoangioma developed, but complete remission was achieved in all patients. CONCLUSIONS: Although further studies are mandatory, surgical closure of ventricular septal defect may be an effective treatment option even for children with trisomy 18. | F13: Interdiscip Cardiovasc Thorac Surg | G13: Journal Article | H13: A | I13: Incluir | J13: A | N13: =HYPERLINK("https://pubmed.ncbi.nlm.nih.gov/39854275/","abrir") -> abrir | O13: =IF(B13 < 2024, FALSE() , TRUE()) -> TRUE
A14: 39937286 | B14: 2025 | C14: Zanin A | D14: Early assessment of clinical complexity and home care in patients affected by trisomy 13 and 18. | E14: PURPOSE: Trisomy 13 and 18 consist of a recurrent pattern of multiple congenital anomalies. The aim of this study was to analyze the clinical characteristics and disease trajectory of a cohort of children with trisomy 13 and 18 followed up by an Italian pediatric palliative care service. METHODS: A single-center retrospective observational study was conducted examining the medical records of patients with trisomy 13 and 18 seen in the Pediatric Palliatives Care (PPC) center of the University Hospital of Padua from 2007 to 2022. RESULTS: Seventeen patients were included in the analysis. All were born alive; four children are still alive and only three (23%) died at home. All presented high care complexity, as estimated by ACCAPED index (median 86, range 38-129). The median time to receive care from PPC was 3 months (0-108). All patients' parents shared an advance care plan with the PPC team: 13/17 patients (76%) accepted a do not resuscitate (DNR) order. Approximately 12% of patients received at least one surgery. The trend of survival compared with other cohorts reported in the literature does not appear to differ significantly after the initial stages. CONCLUSIONS: The possible recognition of an early evolution toward medical complexity and the availability of home care resources and programs are crucial factors in the management of these children. These indices could become a driving factor in the definition of new outcomes that are more patient-oriented, in addition to mortality. WHAT IS KNOWN: • Trisomy 13 and 18 are serious genetic conditions with high mortality rates. In the last years medical interventions including surgery are being offered more frequently, though the appropriateness of these interventions is still debated. WHAT IS NEW: • The study emphasizes the crucial role of early referral to specialized pediatric palliative care teams and the coordination they provide enabling families to care for their children at home, even with complex medical needs. | F14: Eur J Pediatr | G14: Journal Article; Observational Study | H14: A | I14: Incluir | J14: A | N14: =HYPERLINK("https://pubmed.ncbi.nlm.nih.gov/39937286/","abrir") -> abrir | O14: =IF(B14 < 2024, FALSE() , TRUE()) -> TRUE
A15: 40010013 | B15: 2025 | C15: Mannava SV | D15: Gastrostomy Tube Placement in Patients With Trisomy 13 and 18: Surgical Decision Making and Outcomes. | E15: PURPOSE: Trisomy 13 (T13) and trisomy 18 (T18) are chromosomal abnormalities which portend high rates of feeding dysfunction and infant mortality risk. Although gastrostomy tube (GT) placement is commonly performed in this population, there is limited data assessing outcomes associated with this procedure. Our aim was to determine survival outcomes among GT and non-GT patients with T13/18. METHODS: We performed a retrospective cohort study of patients with T13 and T18 treated at our institution from 2005 through 2020. We compared baseline characteristics and survival data between GT and non-GT patients and performed multivariable survival analysis. RESULTS: We analyzed a total of 86 patients (23 GT, 63 non-GT). Over one-third of GT patients underwent the procedure during initial admission and most GTs were used for longer than one year (60.9 %). Significantly more GT patients survived initial discharge (87 % vs. 57.1 %, p < 0.001) and were alive at follow-up (43.5 % vs. 6.3 %, p < 0.001) compared to non-GT patients. Thirty-day post-discharge survival was determined solely by GT status and not impacted by predictors. GT patients had reduced overall mortality risk compared to non-GT patients in the first year of life (HR = 0.10 [95 % CI 0.04-0.29], p < 0.001) and during the fifteen-year study period (HR = 0.15 [95 % CI 0.06-0.35], p < 0.001). CONCLUSIONS: GT status predicted 30-day post-discharge survival in our cohort. GT patients had reduced overall mortality risk compared to non-GT patients. In patients with expected survival to initial discharge and feeding difficulty, GT placement at or after initial admission may be associated with improved survival outcomes. LEVEL OF EVIDENCE: III. | F15: J Pediatr Surg | G15: Journal Article | H15: A | I15: Incluir | J15: A | N15: =HYPERLINK("https://pubmed.ncbi.nlm.nih.gov/40010013/","abrir") -> abrir | O15: =IF(B15 < 2024, FALSE() , TRUE()) -> TRUE
A16: 40537699 | B16: 2025 | C16: de Sá Bittencourt Câmara Bastos C | D16: Outcomes of heart surgery in neonates with trisomy 13 and 18: a systematic review with metanalysis. | E16: This systematic review and meta-analysis aimed to evaluate the clinical outcomes of cardiac surgery in neonates with trisomy 13 (T13) or trisomy 18 (T18) compared to those managed with palliative care. A literature search was conducted in PubMed® and EMBASE®, following PRISMA guidelines, and included five retrospective cohort studies (1627 patients). Outcomes analyzed included in-hospital mortality, survival at 12 months, length of stay (LOS), hospital discharge rates, and the need for mechanical ventilation. The meta-analysis showed that cardiac surgery significantly reduced the odds of in-hospital mortality (OR 0.12, CI 95% 0.03-0.42, p < 0.01), increased survival at 12 months (OR 19.77, CI 95% 5.12-76.36, p < 0.01), and improved discharge rates (OR 12.53, CI 95% 3.63-43.22, p < 0.01). However, limited data were available on quality of life and mechanical ventilation duration. Conclusion: Despite the positive impact of cardiac surgery on survival and discharge rates, the evidence remains low quality, as the included studies were primarily retrospective cohorts with moderate risk of bias. The findings highlight the importance of involving families in the decision-making process, given their differing perspectives on quality of life. Further high-quality studies, such as randomized controlled trials, are needed to provide stronger evidence on this topic. | F16: Eur J Pediatr | G16: Journal Article; Systematic Review; Meta-Analysis | H16: A | I16: Incluir | J16: A | N16: =HYPERLINK("https://pubmed.ncbi.nlm.nih.gov/40537699/","abrir") -> abrir | O16: =IF(B16 < 2024, FALSE() , TRUE()) -> TRUE
A17: 40599664 | B17: 2025 | C17: Armour E | D17: Liveborn children with trisomy 18: A retrospective review. | E17: BACKGROUND: Historically, children born alive with trisomy 18 were considered to have a lethal genetic condition such that no medical interventions were provided. While survival is now recognized to be possible, these children's lives include aspects of technological dependency, medical complexity, and neurodevelopmental disabilities. OBJECTIVES: The primary aim of this study was to describe the outcomes of a contemporary Canadian population-based cohort of children born alive with trisomy 18. METHODS: A retrospective study was conducted to review the records of children born alive with trisomy 18 from January 2012 to December 2023 in Central/Northern Alberta. Demographic and clinical information were abstracted, including features reported in the literature associated with morbidity and mortality. Outcomes were described, including technological dependency, time spent in the hospital, and survival. RESULTS: In total, 37 liveborn infants with complete trisomy 18 were identified. While most died in hospital following medical-surgical interventions and/or comfort-care palliation, nine were discharged home. All of these children had been born at term with a birthweight ≥1750 g. While they relied on medical technologies such as home oxygen and feeding tubes at the time of discharge, most were able to spend a considerable amount of time at home rather than being re-hospitalized. At the time of this review, four remain alive varying in age from 6 to 9 years. CONCLUSIONS: Trisomy 18 is not a homogeneous clinical condition. Some children may have their lives extended to spend their lives at home with their families. | F17: Paediatr Child Health | G17: Journal Article | H17: A | I17: Incluir | J17: A | N17: =HYPERLINK("https://pubmed.ncbi.nlm.nih.gov/40599664/","abrir") -> abrir | O17: =IF(B17 < 2024, FALSE() , TRUE()) -> TRUE
A18: 40920381 | B18: 2025 | C18: Ludorf KL | D18: Long-Term Survival Among Children With Trisomy 13 and Trisomy 18 by Cytogenetic Status. | E18: IMPORTANCE: Trisomy 13 (T13) and trisomy 18 (T18) are chromosomal abnormalities with high mortality rates in the first year of life. Understanding differences in long-term survival between children with full vs mosaic or partial trisomy is crucial for prognosis and health care planning. OBJECTIVE: To examine the differences in 10-year survival between children with full T13 and T18 vs those with mosaic or partial trisomy. DESIGN, SETTING, AND PARTICIPANTS: This retrospective, population-based cohort study assessed liveborn infants with T13 and T18 in the Texas Birth Defects Registry (deliveries from January 1, 1999, to December 31, 2008). Follow-up was through December 31, 2018 (the last date available at the time of analyses) to allow for 10 years of follow-up for all infants. All analyses were conducted from January 1, 2022, to December 31, 2024. EXPOSURES: Cytogenetic status (full trisomy vs mosaic or partial trisomy). MAIN OUTCOMES AND MEASURES: The primary outcome was survival to 10 years of age, assessed using Kaplan-Meier survival estimates. The association between cytogenetic status and mortality by 10 years of age was assessed using Cox proportional hazards regression to generate hazard ratios (HRs). Population attributable fraction was calculated to determine the percentage of survival attributable to mosaic or partial trisomy status. RESULTS: The study cohort included 798 infants (463 female infants [58.0%]; mean [SD] maternal age, 30.9 [8.0] years) with T13 (n = 295) or T18 (n = 503). Among all cases with T13, 25 infants (8.5%; 95% CI, 5.5%-12.3%) survived to 10 years of age. Similarly, among all infants with T18, 43 (8.6%; 95% CI, 6.3%-11.3%) survived to 10 years of age. Kaplan-Meier survival estimates to 10 years of age were statistically significantly higher among children with mosaic or partial trisomy (13 [25.0%] and 14 [43.8%], respectively) compared with full trisomy (12 [4.9%] and 29 [6.6%], respectively) (both P < .001). Infants with full trisomy had statistically significantly increased 10-year mortality hazards compared with those with mosaic or partial trisomy for both T13 (HR, 2.00; 95% CI, 1.42-2.82) and T18 (HR, 3.34; 95% CI, 2.08-5.38). The results of the calculated proportion of 10-year survival due to the presence of nonfull trisomy status (population attributable fraction) was 41.7% for children with T13 and 27.9% for children with T18. CONCLUSIONS AND RELEVANCE: The findings of this cohort study of infants with T13 and T18 support differences in long-term survival based on cytogenetic status and emphasize the need to potentially reassess the context of these conditions generally being considered incompatible with life, particularly for those with mosaic trisomies. These findings offer context surrounding treatment decisions, such as withholding interventions, for affected infants in the future. | F18: JAMA Netw Open | G18: Journal Article; Research Support, Non-U.S. Gov't | H18: A | I18: Incluir | J18: A | M18: Sobrevida de longo prazo por status citogenético (completa x mosaico/parcial). | N18: =HYPERLINK("https://pubmed.ncbi.nlm.nih.gov/40920381/","abrir") -> abrir | O18: =IF(B18 < 2024, FALSE() , TRUE()) -> TRUE
A19: 41420650 | B19: 2025 | C19: Reischer T | D19: Clinical course and perinatal management of fetuses and newborns affected by trisomy 13 and 18: a retrospective single-centre cohort study. | E19: Objectives Trisomy 13 (T13) and 18 (T18) are lethal chromosomal abnormalities. While the prognosis is generally poor, recent evidence suggests that some infants with T13 and T18 are able to survive longer than previously supposed. These findings underline the importance of an individualised approach to perinatal/neonatal care. Methods This retrospective study included 193 pregnancies with T13 and T18 in a single tertiary center between 2005 and 2023. Fetal and maternal characteristics, overall survival, and perinatal and postnatal management were analysed. Results Of 193 affected fetuses, 142 (73.6%) were diagnosed with T18 and 51 (26.4%) with T13. Associated malformations were present in 90.7% (175 cases), with congenital heart defects being the most common (42%). A total of 161 (83,4%) women opted for termination of pregnancy (TOP). Gestational age at diagnosis was significantly higher among women opting to continue pregnancy compared to those opting for TOP. Among women continuing pregnancy, 65.6% (21/32) experienced intrauterine fetal death. Eleven pregnancies resulted in live births. Survival times for infants born alive ranged from 6 min to 60 days, with a median survival time of 18 h. Newborns affected by T18 lived significantly longer than those with T13 (median 33 h vs 6.5 h).Conclusion: The duration of survival in infants with T13 and T18 remains highly variable and difficult to predict. Management strategies must therefore be clarified within an interdisciplinary framework, supporting families through informed, individualised decision-making while balancing the poor prognosis with a focus on comfort, dignity, and quality of life. | F19: Eur J Pediatr | G19: Journal Article | H19: A | I19: Incluir | J19: A+B | N19: =HYPERLINK("https://pubmed.ncbi.nlm.nih.gov/41420650/","abrir") -> abrir | O19: =IF(B19 < 2024, FALSE() , TRUE()) -> TRUE
A20: 37822198 | B20: 2024 | C20: Mehl JM | D20: Causes of death in individuals with trisomy 18 after the first year of life. | E20: Mortality in individuals with trisomy 18 has significantly decreased over the past 20 years, but there is scant literature addressing the prognosis and cause of death in individuals with trisomy 18 and survival past the first year of life (YOL). This study analyzed factors associated with mortality and cause of death in a retrospective cohort of 174 individuals with trisomy 18 and survival past the first YOL, the largest such series to date. Data were collected via retrospective survey of parents of affected individuals. Prenatal diagnosis of trisomy 18; postnatal respiratory distress; maternal age > 35 years; birthweight <2000 g; brain and spinal cord defect(s); atrial and/or ventricular septal defect(s); inability to feed orally without medical assistance; and failure to meet sitting and rolling milestones were associated with mortality in this sample. Cause of death was compared between our cohort of individuals with trisomy 18 and existing literature on those with mortality before the first YOL. Individuals with trisomy 18 with mortality after the first YOL demonstrated a predominance of infectious (n = 10/22) and postoperative (n = 6/22) contributing causes of death, in contrast to the existing literature, which shows a predominance of cardiopulmonary causes of death (e.g., cardiopulmonary arrest, pulmonary hypertension). These findings demonstrate that individuals with trisomy 18 and survival past the first YOL have unique medical needs, but further research is needed to develop clinical guidelines for this growing population. | F20: Am J Med Genet A | G20: Journal Article | H20: A+B | I20: Incluir | J20: A | M20: Destaque: maior série de sobreviventes além de 1 ano (174; questionário de pais). Diagnóstico pré-natal entre os fatores associados à mortalidade. | N20: =HYPERLINK("https://pubmed.ncbi.nlm.nih.gov/37822198/","abrir") -> abrir | O20: =IF(B20 < 2024, FALSE() , TRUE()) -> TRUE
A21: 38071520 | B21: 2024 | C21: Kutsukake M | D21: Treatment courses and outcomes of oesophageal atresia in patients with trisomy 18: a case series of 271 patients from a nationwide database in Japan. | E21: OBJECTIVE: To describe characteristics, treatments and clinical outcomes of patients with trisomy 18 and oesophageal atresia, using a nationwide database in Japan. DESIGN: Descriptive study using a retrospective cohort. SETTING: A nationwide inpatient database including 90% of hospitals with neonatal intensive care units in Japan. PATIENTS: Patients hospitalised within a day after birth for both oesophageal atresia and trisomy 18 between July 2010 and March 2020. INTERVENTIONS: Radical surgery for oesophageal atresia. MAIN OUTCOME MEASURES: Characteristics, treatment course and outcomes. RESULTS: Among 271 patients with both oesophageal atresia and trisomy 18, 70 patients underwent radical surgery for oesophageal atresia. Patients who underwent radical surgery were less likely to have severe cardiac anomalies (17% vs 32%; p=0.020), but more likely to undergo cardiac surgery (21% vs 9.5%; p=0.012) than those who did not. The overall in-hospital mortality was lower (54% vs 79%; p<0.001) and the median age at death was higher (210 days vs 39 days; p<0.001) in patients who underwent radical surgery than the others. Postoperative mortality within 30 days after radical surgery was 5.7%. Patients who underwent radical surgery were likely to be discharged to home (50% vs 18%; p<0.001), whereas the age at home discharge (median 314 days vs 216 days; p=0.19) and the requirement for each home treatment did not differ significantly by radical surgery. CONCLUSION: This study provides information that will aid the clinical decision-making process for patients with oesophageal atresia and trisomy 18. Radical surgery may be a safe and feasible treatment option. | F21: Arch Dis Child Fetal Neonatal Ed | G21: Journal Article | H21: A | I21: Incluir | J21: A | N21: =HYPERLINK("https://pubmed.ncbi.nlm.nih.gov/38071520/","abrir") -> abrir | O21: =IF(B21 < 2024, FALSE() , TRUE()) -> TRUE
A22: 38340889 | B22: 2024 | C22: Greenberg JW | D22: Contemporary Trends in Cardiac Surgical Care for Trisomy 13 and 18 Patients Admitted to Hospitals in the United States. | E22: OBJECTIVE: To assess rates of cardiac surgery and the clinical and demographic features that influence surgical vs nonsurgical treatment of congenital heart disease (CHD) in patients with trisomy 13 (T13) and trisomy 18 (T18) in the United States. STUDY DESIGN: A retrospective study was performed using the Pediatric Health Information System. All hospital admissions of children (<18 years of age) with T13 and T18 in the United States were identified from 2003 through 2022. International Classifications of Disease (ICD) codes were used to identify presence of CHD, extracardiac comorbidities/malformations, and performance of cardiac surgery. RESULTS: Seven thousand one hundred thirteen patients were identified. CHD was present in 62% (1625/2610) of patients with T13 and 73% (3288/4503) of patients with T18. The most common CHD morphologies were isolated atrial/ventricular septal defects (T13 40%, T18 42%) and aortic hypoplasia/coarctation (T13 21%, T18 23%). Single-ventricle morphologies comprised 6% (100/1625) of the T13 and 5% (167/3288) of the T18 CHD cohorts. Surgery was performed in 12% of patients with T13 plus CHD and 17% of patients with T18 plus CHD. For all cardiac diagnoses, <50% of patients received surgery. Nonsurgical patients were more likely to be born prematurely (P < .05 for T13 and T18). The number of extracardiac comorbidities was similar between surgical/nonsurgical patients with T13 (median 2 vs 2, P = .215) and greater in surgical vs nonsurgical patients with T18 (median 3 vs 2, P < .001). Hospital mortality was <10% for both surgical cohorts. CONCLUSIONS: Patients with T13 or T18 and CHD receive surgical palliation, but at a low prevalence (≤17%) nationally. Given operative mortality <10%, opportunity exists perhaps for quality improvement in the performance of cardiac surgery for these vulnerable patient populations. | F22: J Pediatr | G22: Journal Article | H22: A | I22: Incluir | J22: A | N22: =HYPERLINK("https://pubmed.ncbi.nlm.nih.gov/38340889/","abrir") -> abrir | O22: =IF(B22 < 2024, FALSE() , TRUE()) -> TRUE
A23: 38884184 | B23: 2024 | C23: Tamaki S | D23: Impact of definitive surgery for esophageal atresia on long-term outcomes in patients with trisomy 18. | E23: This study investigates the long-term outcomes of palliative and definitive surgeries for esophageal atresia (EA) in patients with trisomy 18 syndrome. A retrospective study included 25 cases undergoing EA surgery at our center between 2008 and 2022. The Palliative group (n = 16) comprised 13 cases with esophageal banding and 3 with tracheoesophageal fistula (TEF) division. The Definitive group (n = 9) included 5 cases with primary repair and 4 with staged repair following TEF division. The patient characteristics exhibited no significant differences between the groups. In the Definitive group, 56% (5/9) were successfully weaned off mechanical ventilation, compared with none in the Palliative group (p = 0.002). Survival-to-discharge rates were 31% (5/16) in the Palliative group and 67% (6/9) in the Definitive group. Home ventilator management was required for all 5 cases that required ventilation in the Palliative group, whereas only 17% (1/6) in the Definitive group needed it. The Palliative group also required continuous oral suction for persistent saliva removal, with two cases undergoing laryngotracheal separation. Overall, definitive surgery for EA in patients with trisomy 18 syndrome may provide enhanced respiratory stability, thereby improving the survival-to-discharge rate and overall quality of life for patients and their families. | F23: Am J Med Genet A | G23: Journal Article | H23: A | I23: Incluir | J23: A | N23: =HYPERLINK("https://pubmed.ncbi.nlm.nih.gov/38884184/","abrir") -> abrir | O23: =IF(B23 < 2024, FALSE() , TRUE()) -> TRUE
A24: 39296445 | B24: 2024 | C24: Greene CL | D24: Operative and nonoperative outcomes in patients with trisomy 13 and 18 with congenital heart disease. | E24: OBJECTIVE: To evaluate the short- and long-term outcomes of cardiac repair versus nonoperative management in patients with trisomy 13 and trisomy 18 with congenital heart disease. METHODS: An institutional review board-approved, retrospective review was undertaken to identify all patients admitted with trisomy 13/18 and congenital heart disease. Patients were divided into 2 cohorts (operated vs nonoperated) and compared. RESULTS: Between 1985 and 2023, 62 patients (34 operated and 28 nonoperated) with trisomy 13 (n = 9) and trisomy 18 (n = 53) were identified. The operated cohort was 74% girls, underwent mainly The Society of Thoracic Surgeons-European Association for Cardio-Thoracic Surgery mortality category 1 procedures (n = 24 [71%]) at a median age of 2.5 months (interquartile range [IQR], 1.3-4.5 months). This compares with the nonoperative cohort where 64% (n = 18) would have undergone The Society of Thoracic Surgeons-European Association for Cardio-Thoracic Surgery mortality category 1 procedures if surgery would have been elected. The most common diagnosis was ventricular septal defect. Postoperative median intensive care unit stay was 6.5 days (IQR, 3.7-15 days) with a total hospital length of stay of 15 days (IQR, 11-49 days). Thirty-day postoperative survival was 94%. There were 5 in-hospital deaths in the operated and 7 in the nonoperated cohort. Median follow-up was 15.4 months (IQR, 4.3-48.7 months) for the operated and 11.2 months (IQR, 1.2-48.3 months) for the nonoperated cohorts. One-year survival was 79% operated versus 51.5% nonoperated (P < .003). Nonoperative treatment had an increased risk of mortality (hazard ratio, 3.28; 95% CI, 1.46-7.4; P = .004). CONCLUSIONS: Controversy exists regarding the role of primary cardiac repair in patients with trisomy 13/18 and congenital heart disease. Cardiac repair can be performed safely with low early mortality and operated patients had higher long-term survival compared with nonoperated in our cohort. | F24: JTCVS Open | G24: Journal Article | H24: A | I24: Incluir | J24: A | N24: =HYPERLINK("https://pubmed.ncbi.nlm.nih.gov/39296445/","abrir") -> abrir | O24: =IF(B24 < 2024, FALSE() , TRUE()) -> TRUE
A25: 40016985 | B25: 2024 | C25: Schlosser MP | D25: Liveborn children with trisomy 18: A scoping review. | E25: BACKGROUND: There have been an increasing number of publications related to trisomy 18 associated with a shift in the philosophy of care. The objective of this review is to understand the scope of contemporary literature informing the care of children born alive with trisomy 18. METHODS: Included was peer-reviewed, primary literature in MEDLINE, Embase, CINAHL, Scopus, Web of Science, and Cochrane Library from 2012 to 2023 reporting outcomes of children born alive with trisomy 18. Data extraction involved descriptive statistics of the types of studies, and an inductive thematic analysis of the questions addressed by the studies. RESULTS: Of 4628 records identified, 229 met inclusion criteria. Key themes were organized around the domains: What is trisomy 18? What are the chances of survival with trisomy 18? What can be done to improve the chances of survival with trisomy 18? How do children with trisomy 18 die? Do surgical interventions provide a benefit? Are there non-surgical options? What knowledge is informing medical management? How is life described for children with trisomy 18? What are children with trisomy 18 like as babies and as they get older? What is life like for families caring for children with trisomy 18? CONCLUSIONS: A sizeable number of publications grouped trisomy 18 with other syndromes. Relatively few showed the longitudinal evolution of medical issues associated with trisomy 18, nor did they unfold the clinical heterogeneity of this population. This review shows the limited knowledge base guiding decision-making and care for children born alive with trisomy 18. | F25: J Neonatal Perinatal Med | G25: Journal Article; Scoping Review | H25: A | I25: Incluir | J25: A | M25: Destaque: revisão de escopo sobre nascidos vivos com T18. | N25: =HYPERLINK("https://pubmed.ncbi.nlm.nih.gov/40016985/","abrir") -> abrir | O25: =IF(B25 < 2024, FALSE() , TRUE()) -> TRUE
A26: 36402594 | B26: 2023 | C26: Hafezi N | D26: Surgical History and Outcomes in Trisomy 13 and 18: A Thirty-year Review. | E26: BACKGROUND: Patients with Trisomy 13(T13) and 18(T18) have many comorbidities that may require surgical intervention. However, surgical care and outcomes are not well described, making patient selection and family counseling difficult. Here the surgical history and outcomes of T13/ T18 patients are explored. METHODS: A retrospective review of patients with T13 or T18 born between 1990 and 2020 and cared for at a tertiary children's hospital (Riley Hospital for Children, Indianapolis IN) was conducted, excluding those with insufficient records. Primary outcomes of interest were rates of mortality overall and after surgery. Factors that could predict mortality outcomes were also assessed. RESULTS: One-hundred-seventeen patients were included, with 65% T18 and 35% T13. More than half of patients(65%) had four or more comorbidities. Most deaths occurred by three months at median 42.0 days. Variants of classic trisomies (mosaicism, translocation, partial duplication; p = 0.001), higher birth weight(p = 0.002), and higher gestational age(p = 0.01) were associated with lower overall mortality, while cardiac(p = 0.002) disease was associated with higher mortality. Over half(n = 64) underwent surgery at median age 65 days at time of first procedure. The most common surgical procedures were general surgical. Median survival times were longer in surgical rather than nonsurgical patients(p<0.001). Variant trisomy genetics(p = 0.002) was associated with lower mortality after surgery, while general surgical comorbidities(p = 0.02), particularly tracheoesophageal fistula/esophageal atresia(p = 0.02), were associated with increased mortality after surgery. CONCLUSIONS: Trisomy 13 and 18 patients have vast surgical needs. Variant trisomy was associated with lower mortality after surgery while general surgical comorbidities were associated with increased mortality after surgery. Those who survived to undergo surgery survived longer overall. LEVEL OF EVIDENCE: III. | F26: J Pediatr Surg | G26: Journal Article | H26: A | I26: Incluir | J26: A | N26: =HYPERLINK("https://pubmed.ncbi.nlm.nih.gov/36402594/","abrir") -> abrir | O26: =IF(B26 < 2024, FALSE() , TRUE()) -> FALSE
